Workbook

Sheet PSA Model
A1: TWO-STAGE PSA MODEL | N1: SUMMARY & EQUATIONS
A3: INPUTS | H3: LEGEND | N3: KEY PERFORMANCE METRICS
A4: Total Feed (SCFM): | B4: 1100 | C4: Stage 2 Tail Recycle Frac: | D4: 1 | E4: Product Recycle Frac: | F4: 0 | I4: Input cells (editable) | N4: H2 Recovery: | O4: =K17/B17*100 -> 79.475485 | P4: Target: | Q4: 0.796
I5: Calculated cells (protected) | N5: Product H2 Purity: | O5: =K28 -> 99.999435 | P5: Target: | Q5: >99.99%
A6: Component | B6: Feed % | C6: Stage 1 Removal % | D6: Stage 2 Removal % | N6: Feed Flow (SCFM): | O6: =B4 -> 1100 | P6: Xebec: | Q6: 1100
A7: H2 | B7: 32.08 | C7: 18 | D7: 15 | N7: Net Product (SCFM): | O7: =K24 -> 280.42663 | P7: Xebec: | Q7: 263
A8: CO | B8: 38.22 | C8: 98 | D8: 99.99 | N8: Exhaust (SCFM): | O8: =F24 -> 819.57337 | P8: Xebec: | Q8: 837
A9: CO2 | B9: 21.98 | C9: 98 | D9: 99.99 | N9: S2 Tail Vent (SCFM): | O9: =G24 -> 0
A10: H2O | B10: 4.85 | C10: 99 | D10: 99.99 | N10: Mass Balance Check: | O10: =IF(ABS(L24)<0.0001,"✓ OK","✗ Error") -> ✓ OK
A11: N2 | B11: 0.5 | C11: 95 | D11: 99.99
A12: O2 | B12: 0.5 | C12: 81 | D12: 99.99 | N12: MODEL EQUATIONS
A13: CH4 | B13: 1.88 | C13: 99 | D13: 99.99 | N13: Algebraic Solution (eliminates circular references):
A15: MASS BALANCE (SCFM) | B15: From Gasifier | E15: Net PSA 1 Feed | F15: PSA 1 Tail | G15: PSA 2 Recycle | H15: PSA 2 Feed | I15: PSA 2 Outlet Gross | J15: PSA 2 Tail | K15: PSA 2 Outlet Net | N15: Mixed Feed (per component i):
A16: Component | B16: 1 Fresh Feed | C16: 4 S2 Tail Recy | D16: 3R Prod Recycle | E16: 5A Mixed Feed | F16: 2 Exhaust | G16: S2 Tail Vent | H16: 6 Interstage | I16: 3G Gross Prod | J16: Stage 2 Tail | K16: 3N Net Prod | L16: Check | N16: Mᵢ = Fᵢ / [ 1 - (1-R₁ᵢ)·(R₂ᵢ·r_tail + (1-R₂ᵢ)·r_prod) ]
A17: H2 | B17: =$B$4*B7/SUM($B$7:$B$13) -> 352.84472 | C17: =J17*$D$4 -> 49.486773 | D17: =I17*$F$4 -> 0 | E17: =B17/(1 - (1-C7/100)*((D7/100)*$D$4 + (1-D7/100)*$F$4)) -> 402.33149 | F17: =E17*(C7/100) -> 72.419668 | G17: =J17*(1-$D$4) -> 0 | H17: =E17-F17 -> 329.91182 | I17: =H17-J17 -> 280.42505 | J17: =H17*(D7/100) -> 49.486773 | K17: =I17*(1-$F$4) -> 280.42505 | L17: =B17-F17-G17-K17 -> 0
A18: CO | B18: =$B$4*B8/SUM($B$7:$B$13) -> 420.37796 | C18: =J18*$D$4 -> 8.5782667 | D18: =I18*$F$4 -> 0 | E18: =B18/(1 - (1-C8/100)*((D8/100)*$D$4 + (1-D8/100)*$F$4)) -> 428.95623 | F18: =E18*(C8/100) -> 420.3771 | G18: =J18*(1-$D$4) -> 0 | H18: =E18-F18 -> 8.5791246 | I18: =H18-J18 -> 0.00085791246 | J18: =H18*(D8/100) -> 8.5782667 | K18: =I18*(1-$F$4) -> 0.00085791246 | L18: =B18-F18-G18-K18 -> 3.7303494e-14 | N18: Where:
A19: CO2 | B19: =$B$4*B9/SUM($B$7:$B$13) -> 241.75582 | C19: =J19*$D$4 -> 4.9332889 | D19: =I19*$F$4 -> 0 | E19: =B19/(1 - (1-C9/100)*((D9/100)*$D$4 + (1-D9/100)*$F$4)) -> 246.68911 | F19: =E19*(C9/100) -> 241.75533 | G19: =J19*(1-$D$4) -> 0 | H19: =E19-F19 -> 4.9337823 | I19: =H19-J19 -> 0.00049337823 | J19: =H19*(D9/100) -> 4.9332889 | K19: =I19*(1-$F$4) -> 0.00049337823 | L19: =B19-F19-G19-K19 -> 1.0658141e-14 | N19: Fᵢ = Fresh feed flow of component i (SCFM)
A20: H2O | B20: =$B$4*B10/SUM($B$7:$B$13) -> 53.344666 | C20: =J20*$D$4 -> 0.53878058 | D20: =I20*$F$4 -> 0 | E20: =B20/(1 - (1-C10/100)*((D10/100)*$D$4 + (1-D10/100)*$F$4)) -> 53.883446 | F20: =E20*(C10/100) -> 53.344612 | G20: =J20*(1-$D$4) -> 0 | H20: =E20-F20 -> 0.53883446 | I20: =H20-J20 -> 5.3883446e-05 | J20: =H20*(D10/100) -> 0.53878058 | K20: =I20*(1-$F$4) -> 5.3883446e-05 | L20: =B20-F20-G20-K20 -> 2.7755576e-15 | N20: Mᵢ = Mixed feed flow of component i (SCFM)
A21: N2 | B21: =$B$4*B11/SUM($B$7:$B$13) -> 5.4994501 | C21: =J21*$D$4 -> 0.28941427 | D21: =I21*$F$4 -> 0 | E21: =B21/(1 - (1-C11/100)*((D11/100)*$D$4 + (1-D11/100)*$F$4)) -> 5.7888643 | F21: =E21*(C11/100) -> 5.4994211 | G21: =J21*(1-$D$4) -> 0 | H21: =E21-F21 -> 0.28944322 | I21: =H21-J21 -> 2.8944322e-05 | J21: =H21*(D11/100) -> 0.28941427 | K21: =I21*(1-$F$4) -> 2.8944322e-05 | L21: =B21-F21-G21-K21 -> 3.3306691e-16 | N21: R₁ᵢ = Stage 1 removal fraction for component i
A22: O2 | B22: =$B$4*B12/SUM($B$7:$B$13) -> 5.4994501 | C22: =J22*$D$4 -> 1.2898352 | D22: =I22*$F$4 -> 0 | E22: =B22/(1 - (1-C12/100)*((D12/100)*$D$4 + (1-D12/100)*$F$4)) -> 6.7892853 | F22: =E22*(C12/100) -> 5.4993211 | G22: =J22*(1-$D$4) -> 0 | H22: =E22-F22 -> 1.2899642 | I22: =H22-J22 -> 0.00012899642 | J22: =H22*(D12/100) -> 1.2898352 | K22: =I22*(1-$F$4) -> 0.00012899642 | L22: =B22-F22-G22-K22 -> -2.220446e-16 | N22: R₂ᵢ = Stage 2 removal fraction for component i
A23: CH4 | B23: =$B$4*B13/SUM($B$7:$B$13) -> 20.677932 | C23: =J23*$D$4 -> 0.2088469 | D23: =I23*$F$4 -> 0 | E23: =B23/(1 - (1-C13/100)*((D13/100)*$D$4 + (1-D13/100)*$F$4)) -> 20.886779 | F23: =E23*(C13/100) -> 20.677911 | G23: =J23*(1-$D$4) -> 0 | H23: =E23-F23 -> 0.20886779 | I23: =H23-J23 -> 2.0886779e-05 | J23: =H23*(D13/100) -> 0.2088469 | K23: =I23*(1-$F$4) -> 2.0886779e-05 | L23: =B23-F23-G23-K23 -> 4.7184479e-16 | N23: r_tail = Stage 2 tail recycle fraction (0 to 1)
A24: Total | B24: =SUM(B17:B23) -> 1100 | C24: =SUM(C17:C23) -> 65.325206 | D24: =SUM(D17:D23) -> 0 | E24: =SUM(E17:E23) -> 1165.3252 | F24: =SUM(F17:F23) -> 819.57337 | G24: =SUM(G17:G23) -> 0 | H24: =SUM(H17:H23) -> 345.75184 | I24: =SUM(I17:I23) -> 280.42663 | ... K24: =SUM(K17:K23) -> 280.42663 | L24: =B24-F24-G24-K24 -> 0 | N24: r_prod = Product recycle fraction (0 to 1)
A26: COMPOSITION (%) | N26: Stream Calculations (Cell References):
A27: Component | B27: 1 Fresh Feed | C27: 4 S2 Tail Recy | D27: 3R Prod Recycle | E27: 5A Mixed Feed | F27: 2 Exhaust | G27: S2 Tail Vent | H27: 6 Interstage | I27: 3G Gross Prod | J27: Stage 2 Tail | K27: 3N Net Prod | N27: Exhaust (F) = Mixed(E) × R₁ [=E×(C/100)]
A28: H2 | B28: =IF(B$24=0,0,B17/B$24*100) -> 32.076792 | C28: =IF(C$24=0,0,C17/C$24*100) -> 75.754485 | D28: =IF(D$24=0,0,D17/D$24*100) -> 0 | E28: =IF(E$24=0,0,E17/E$24*100) -> 34.525254 | F28: =IF(F$24=0,0,F17/F$24*100) -> 8.8362642 | G28: =IF(G$24=0,0,G17/G$24*100) -> 0 | H28: =IF(H$24=0,0,H17/H$24*100) -> 95.418675 | I28: =IF(I$24=0,0,I17/I$24*100) -> 99.999435 | ... K28: =IF(K$24=0,0,K17/K$24*100) -> 99.999435 | N28: Interstage (H) = Mixed(E) - Exhaust(F) [=E-F]
A29: CO | B29: =IF(B$24=0,0,B18/B$24*100) -> 38.216178 | C29: =IF(C$24=0,0,C18/C$24*100) -> 13.131634 | D29: =IF(D$24=0,0,D18/D$24*100) -> 0 | E29: =IF(E$24=0,0,E18/E$24*100) -> 36.810002 | F29: =IF(F$24=0,0,F18/F$24*100) -> 51.292187 | G29: =IF(G$24=0,0,G18/G$24*100) -> 0 | H29: =IF(H$24=0,0,H18/H$24*100) -> 2.4812954 | I29: =IF(I$24=0,0,I18/I$24*100) -> 0.00030593116 | ... K29: =IF(K$24=0,0,K18/K$24*100) -> 0.00030593116 | N29: Stage 2 Tail (J) = Interstage(H) × R₂ [=H×(D/100)]
A30: CO2 | B30: =IF(B$24=0,0,B19/B$24*100) -> 21.977802 | C30: =IF(C$24=0,0,C19/C$24*100) -> 7.5518919 | D30: =IF(D$24=0,0,D19/D$24*100) -> 0 | E30: =IF(E$24=0,0,E19/E$24*100) -> 21.169122 | F30: =IF(F$24=0,0,F19/F$24*100) -> 29.497705 | G30: =IF(G$24=0,0,G19/G$24*100) -> 0 | H30: =IF(H$24=0,0,H19/H$24*100) -> 1.4269721 | I30: =IF(I$24=0,0,I19/I$24*100) -> 0.00017593843 | ... K30: =IF(K$24=0,0,K19/K$24*100) -> 0.00017593843 | N30: S2 Tail Recycle (C)= S2 Tail(J) × r_tail [=J×$D$4]
A31: H2O | B31: =IF(B$24=0,0,B20/B$24*100) -> 4.849515 | C31: =IF(C$24=0,0,C20/C$24*100) -> 0.82476675 | D31: =IF(D$24=0,0,D20/D$24*100) -> 0 | E31: =IF(E$24=0,0,E20/E$24*100) -> 4.6238978 | F31: =IF(F$24=0,0,F20/F$24*100) -> 6.5088269 | G31: =IF(G$24=0,0,G20/G$24*100) -> 0 | H31: =IF(H$24=0,0,H20/H$24*100) -> 0.15584428 | I31: =IF(I$24=0,0,I20/I$24*100) -> 1.9214811e-05 | ... K31: =IF(K$24=0,0,K20/K$24*100) -> 1.9214811e-05 | N31: S2 Tail Vent (G) = S2 Tail(J) × (1-r_tail) [=J×(1-$D$4)]
A32: N2 | B32: =IF(B$24=0,0,B21/B$24*100) -> 0.49995 | C32: =IF(C$24=0,0,C21/C$24*100) -> 0.44303614 | D32: =IF(D$24=0,0,D21/D$24*100) -> 0 | E32: =IF(E$24=0,0,E21/E$24*100) -> 0.49675956 | F32: =IF(F$24=0,0,F21/F$24*100) -> 0.67101023 | G32: =IF(G$24=0,0,G21/G$24*100) -> 0 | H32: =IF(H$24=0,0,H21/H$24*100) -> 0.083714151 | I32: =IF(I$24=0,0,I21/I$24*100) -> 1.0321531e-05 | ... K32: =IF(K$24=0,0,K21/K$24*100) -> 1.0321531e-05 | N32: Gross Product (I) = Interstage(H) - S2 Tail(J) [=H-J]
A33: O2 | B33: =IF(B$24=0,0,B22/B$24*100) -> 0.49995 | C33: =IF(C$24=0,0,C22/C$24*100) -> 1.9744832 | D33: =IF(D$24=0,0,D22/D$24*100) -> 0 | E33: =IF(E$24=0,0,E22/E$24*100) -> 0.58260863 | F33: =IF(F$24=0,0,F22/F$24*100) -> 0.67099802 | G33: =IF(G$24=0,0,G22/G$24*100) -> 0 | H33: =IF(H$24=0,0,H22/H$24*100) -> 0.37308962 | I33: =IF(I$24=0,0,I22/I$24*100) -> 4.600006e-05 | ... K33: =IF(K$24=0,0,K22/K$24*100) -> 4.600006e-05 | N33: Prod Recycle (D) = Gross(I) × r_prod [=I×$F$4]
A34: CH4 | B34: =IF(B$24=0,0,B23/B$24*100) -> 1.879812 | C34: =IF(C$24=0,0,C23/C$24*100) -> 0.3197034 | D34: =IF(D$24=0,0,D23/D$24*100) -> 0 | E34: =IF(E$24=0,0,E23/E$24*100) -> 1.7923562 | F34: =IF(F$24=0,0,F23/F$24*100) -> 2.5230092 | G34: =IF(G$24=0,0,G23/G$24*100) -> 0 | H34: =IF(H$24=0,0,H23/H$24*100) -> 0.060409742 | I34: =IF(I$24=0,0,I23/I$24*100) -> 7.4482152e-06 | ... K34: =IF(K$24=0,0,K23/K$24*100) -> 7.4482152e-06 | N34: Net Product (K) = Gross(I) × (1-r_prod) [=I×(1-$F$4)]
A35: Sum | B35: =SUM(B28:B34) -> 100 | C35: =SUM(C28:C34) -> 100 | D35: =SUM(D28:D34) -> 0 | E35: =SUM(E28:E34) -> 100 | F35: =SUM(F28:F34) -> 100 | G35: =SUM(G28:G34) -> 0 | H35: =SUM(H28:H34) -> 100 | I35: =SUM(I28:I34) -> 100 | ... K35: =SUM(K28:K34) -> 100
A36: FLAMMABILITY STATUS | N36: H2 Recovery:
A37: H2 LFL/UFL (%) | B37: LFL 4 / UFL 75 | C37: LFL 4 / UFL 75 | D37: LFL 4 / UFL 75 | E37: LFL 4 / UFL 75 | F37: LFL 4 / UFL 75 | G37: LFL 4 / UFL 75 | H37: LFL 4 / UFL 75 | I37: LFL 4 / UFL 75 | J37: LFL 4 / UFL 75 | K37: LFL 4 / UFL 75 | N37: η_H₂ = Net Prod H₂ / Feed H₂ × 100%
A38: Flammability | B38: =IF(B33<0.1,"Safe-Low O2",IF(AND(B28>4,B33>2),"⚠️CRITICAL",IF(B28<4,"Safe-Below LFL",IF(B28>75,"Caution-Rich","⚠️FLAMMABLE")))) -> ⚠️FLAMMABLE | C38: =IF(C33<0.1,"Safe-Low O2",IF(AND(C28>4,C33>2),"⚠️CRITICAL",IF(C28<4,"Safe-Below LFL",IF(C28>75,"Caution-Rich","⚠️FLAMMABLE")))) -> Caution-Rich | D38: =IF(D33<0.1,"Safe-Low O2",IF(AND(D28>4,D33>2),"⚠️CRITICAL",IF(D28<4,"Safe-Below LFL",IF(D28>75,"Caution-Rich","⚠️FLAMMABLE")))) -> Safe-Low O2 | E38: =IF(E33<0.1,"Safe-Low O2",IF(AND(E28>4,E33>2),"⚠️CRITICAL",IF(E28<4,"Safe-Below LFL",IF(E28>75,"Caution-Rich","⚠️FLAMMABLE")))) -> ⚠️FLAMMABLE | F38: =IF(F33<0.1,"Safe-Low O2",IF(AND(F28>4,F33>2),"⚠️CRITICAL",IF(F28<4,"Safe-Below LFL",IF(F28>75,"Caution-Rich","⚠️FLAMMABLE")))) -> ⚠️FLAMMABLE | G38: =IF(G33<0.1,"Safe-Low O2",IF(AND(G28>4,G33>2),"⚠️CRITICAL",IF(G28<4,"Safe-Below LFL",IF(G28>75,"Caution-Rich","⚠️FLAMMABLE")))) -> Safe-Low O2 | H38: =IF(H33<0.1,"Safe-Low O2",IF(AND(H28>4,H33>2),"⚠️CRITICAL",IF(H28<4,"Safe-Below LFL",IF(H28>75,"Caution-Rich","⚠️FLAMMABLE")))) -> Caution-Rich | I38: =IF(I33<0.1,"Safe-Low O2",IF(AND(I28>4,I33>2),"⚠️CRITICAL",IF(I28<4,"Safe-Below LFL",IF(I28>75,"Caution-Rich","⚠️FLAMMABLE")))) -> Safe-Low O2 | ... K38: =IF(K33<0.1,"Safe-Low O2",IF(AND(K28>4,K33>2),"⚠️CRITICAL",IF(K28<4,"Safe-Below LFL",IF(K28>75,"Caution-Rich","⚠️FLAMMABLE")))) -> Safe-Low O2 | N38: η_H₂ = K17 / B17 × 100%
A39: ⚠️ = Concern
N40: SAFETY WARNINGS
N41: S2 Tail H2%: | O41: =J28 -> 75.754485
N42: S2 Tail O2%: | O42: =J33 -> 1.9744832
N43: Status: | O43: =J38 -> Caution-Rich
...

Sheet PFD

Sheet Sensitivity
A1: SENSITIVITY ANALYSIS
A3: H2 RECOVERY vs RECYCLE FRACTIONS
A5: Current S2 Tail Recycle: | B5: ='PSA Model'!D4 -> 1
A6: Current Product Recycle: | B6: ='PSA Model'!F4 -> 0
A8: S2 Tail Recycle | B8: Product Recycle | C8: H2 Recovery % | D8: H2 Purity % | E8: Net Product SCFM | F8: S2 Tail O2%
A9: 0 | B9: 0 | C9: =(1-'PSA Model'!C7/100)*(1-'PSA Model'!D7/100)*(1-B9)/(1-(1-'PSA Model'!C7/100)*(('PSA Model'!D7/100)*A9+(1-'PSA Model'!D7/100)*B9))*100 -> 69.7 | D9: ='PSA Model'!K28 -> 99.999435 | E9: ='PSA Model'!B4*('PSA Model'!B7/100)*(C9/100) -> 245.95736 | F9: ='PSA Model'!J33 -> 1.9744832
A10: 0.1 | B10: 0 | C10: =(1-'PSA Model'!C7/100)*(1-'PSA Model'!D7/100)*(1-B10)/(1-(1-'PSA Model'!C7/100)*(('PSA Model'!D7/100)*A10+(1-'PSA Model'!D7/100)*B10))*100 -> 70.567986 | D10: ='PSA Model'!K28 -> 99.999435 | E10: ='PSA Model'!B4*('PSA Model'!B7/100)*(C10/100) -> 249.02031 | F10: ='PSA Model'!J33 -> 1.9744832
A11: 0.2 | B11: 0 | C11: =(1-'PSA Model'!C7/100)*(1-'PSA Model'!D7/100)*(1-B11)/(1-(1-'PSA Model'!C7/100)*(('PSA Model'!D7/100)*A11+(1-'PSA Model'!D7/100)*B11))*100 -> 71.457863 | D11: ='PSA Model'!K28 -> 99.999435 | E11: ='PSA Model'!B4*('PSA Model'!B7/100)*(C11/100) -> 252.16051 | F11: ='PSA Model'!J33 -> 1.9744832
A12: 0.3 | B12: 0 | C12: =(1-'PSA Model'!C7/100)*(1-'PSA Model'!D7/100)*(1-B12)/(1-(1-'PSA Model'!C7/100)*(('PSA Model'!D7/100)*A12+(1-'PSA Model'!D7/100)*B12))*100 -> 72.37047 | D12: ='PSA Model'!K28 -> 99.999435 | E12: ='PSA Model'!B4*('PSA Model'!B7/100)*(C12/100) -> 255.38092 | F12: ='PSA Model'!J33 -> 1.9744832
A13: 0.4 | B13: 0 | C13: =(1-'PSA Model'!C7/100)*(1-'PSA Model'!D7/100)*(1-B13)/(1-(1-'PSA Model'!C7/100)*(('PSA Model'!D7/100)*A13+(1-'PSA Model'!D7/100)*B13))*100 -> 73.306689 | D13: ='PSA Model'!K28 -> 99.999435 | E13: ='PSA Model'!B4*('PSA Model'!B7/100)*(C13/100) -> 258.68464 | F13: ='PSA Model'!J33 -> 1.9744832
A14: 0.5 | B14: 0 | C14: =(1-'PSA Model'!C7/100)*(1-'PSA Model'!D7/100)*(1-B14)/(1-(1-'PSA Model'!C7/100)*(('PSA Model'!D7/100)*A14+(1-'PSA Model'!D7/100)*B14))*100 -> 74.267448 | D14: ='PSA Model'!K28 -> 99.999435 | E14: ='PSA Model'!B4*('PSA Model'!B7/100)*(C14/100) -> 262.07497 | F14: ='PSA Model'!J33 -> 1.9744832
A15: 0.5 | B15: 0.1 | C15: =(1-'PSA Model'!C7/100)*(1-'PSA Model'!D7/100)*(1-B15)/(1-(1-'PSA Model'!C7/100)*(('PSA Model'!D7/100)*A15+(1-'PSA Model'!D7/100)*B15))*100 -> 72.203039 | D15: ='PSA Model'!K28 -> 99.999435 | E15: ='PSA Model'!B4*('PSA Model'!B7/100)*(C15/100) -> 254.79008 | F15: ='PSA Model'!J33 -> 1.9744832
A16: 0.5 | B16: 0.2 | C16: =(1-'PSA Model'!C7/100)*(1-'PSA Model'!D7/100)*(1-B16)/(1-(1-'PSA Model'!C7/100)*(('PSA Model'!D7/100)*A16+(1-'PSA Model'!D7/100)*B16))*100 -> 69.778501 | D16: ='PSA Model'!K28 -> 99.999435 | E16: ='PSA Model'!B4*('PSA Model'!B7/100)*(C16/100) -> 246.23437 | F16: ='PSA Model'!J33 -> 1.9744832
A17: 0.6 | B17: 0.1 | C17: =(1-'PSA Model'!C7/100)*(1-'PSA Model'!D7/100)*(1-B17)/(1-(1-'PSA Model'!C7/100)*(('PSA Model'!D7/100)*A17+(1-'PSA Model'!D7/100)*B17))*100 -> 73.23993 | D17: ='PSA Model'!K28 -> 99.999435 | E17: ='PSA Model'!B4*('PSA Model'!B7/100)*(C17/100) -> 258.44906 | F17: ='PSA Model'!J33 -> 1.9744832
A18: 0.7 | B18: 0.1 | C18: =(1-'PSA Model'!C7/100)*(1-'PSA Model'!D7/100)*(1-B18)/(1-(1-'PSA Model'!C7/100)*(('PSA Model'!D7/100)*A18+(1-'PSA Model'!D7/100)*B18))*100 -> 74.307036 | D18: ='PSA Model'!K28 -> 99.999435 | E18: ='PSA Model'!B4*('PSA Model'!B7/100)*(C18/100) -> 262.21467 | F18: ='PSA Model'!J33 -> 1.9744832
A20: NOTES:
A21: • H2 Recovery increases with S2 Tail Recycle (more H2 returned to system)
A22: • Product Recycle reduces net output but can improve purity
A23: • S2 Tail O2% remains constant (determined by removal rates, not recycle)
A24: • ⚠️ High S2 Tail Recycle increases internal O2 concentration - monitor carefully
A25: • Change values in PSA Model sheet to see updated results here
A27: KEY FINDINGS
A28: 1. Increasing S2 Tail Recycle from 0% to 50% improves H2 recovery by ~1.3%
A29: 2. Product recycle has diminishing returns - higher recycle = lower net output
A30: 3. Optimal operating point depends on balancing recovery vs. throughput
A31: 4. S2 Tail O2 concentration (~3.5%) remains a safety concern regardless of recycle
A32: 5. For maximum recovery with safety: use S2 Tail Recycle ~50%, Product Recycle ~10%

Sheet O2 Safety Analysis
A1: O2 SAFETY SENSITIVITY ANALYSIS
A2: Critical Stage 1 O2 Removal Thresholds to Keep S2 Tail O2 < 2%
A4: CRITICAL THRESHOLDS
A5: Inlet O2 % | B5: Min Safe S1 Removal % | C5: Safety Margin from 80% | D5: Status at 80% S1
A6: 0.5 | B6: 81 | C6: =B6-80 -> 1 | D6: ⚠️ DANGEROUS
A7: 1 | B7: 90 | C7: =B7-80 -> 10 | D7: ⚠️ DANGEROUS
A8: 2 | B8: 95 | C8: =B8-80 -> 15 | D8: ⚠️ DANGEROUS
A9: 5 | B9: 98 | C9: =B9-80 -> 18 | D9: ⚠️ DANGEROUS
A11: KEY FINDING:
A12: At 0.5% inlet O2, if S1 drops to 80%, S2 Tail O2 = 2.1% → EXPLOSIVE RISK
A13: Minimum safe S1 removal at 0.5% inlet = 81% (only 1% margin!)
A14: RECOMMENDATION: Install O2 analyzer on S2 Tail with 1.5% alarm
A16: S2 TAIL O2% vs STAGE 1 REMOVAL EFFICIENCY
A17: S1 O2 Removal % | B17: 0.5% Inlet | C17: 1.0% Inlet | D17: 2.0% Inlet | E17: 5.0% Inlet | G17: Danger Threshold: | H17: 2 | I17: % O2
A18: 50 | B18: 7.91 | C18: 14.66 | D18: 25.57 | E18: 46.2
A19: 55 | B19: 6.56 | C19: 12.32 | D19: 21.94 | E19: 41.26
A20: 60 | B20: 5.41 | C20: 10.27 | D20: 18.63 | E20: 36.4
A21: 65 | B21: 4.42 | C21: 8.46 | D21: 15.61 | E21: 31.62
A22: 70 | B22: 3.55 | C22: 6.86 | D22: 12.83 | E22: 26.9
A23: 75 | B23: 2.78 | C23: 5.41 | D23: 10.27 | E23: 22.25
A24: 80 | B24: 2.1 | C24: 4.12 | D24: 7.91 | E24: 17.67 | G24: <-- Your concern (80%)
A25: 85 | B25: 1.49 | C25: 2.94 | D25: 5.72 | E25: 13.16
A26: 90 | B26: 0.95 | C26: 1.87 | D26: 3.68 | E26: 8.71
A27: 95 | B27: 0.45 | C27: 0.9 | D27: 1.78 | E27: 4.32 | G27: <-- Current operation
A30: LEGEND
B31: Safe (< 2% O2)
B32: Dangerous (> 2% O2)
A34: Note: S2 Tail contains ~77% H2. With O2 > 2%, this creates an explosive mixture.
A35: The H2/O2 mixture has a very wide flammability range (4-94% H2 in air).
